Caching disabled explicitly for validate.

Step validate has started.

By default, the PandasMaterializer stores data as a .csv file. If you want to store data more efficiently, you can install pyarrow by running 'pip install pyarrow'. This will allow PandasMaterializer to automatically store the data as a .parquet file instead.

/opt/homebrew/anaconda3/envs/mlops_9/lib/python3.11/site-packages/zenml/materializers/pandas_materializer.py:94: UserWarning: Could not infer format, so each element will be parsed individually, falling back to dateutil. To ensure parsing is consistent and as-expected, please specify a format.
  df = pd.read_csv(f, index_col=0, parse_dates=True)


By default, the PandasMaterializer stores data as a .csv file. If you want to store data more efficiently, you can install pyarrow by running 'pip install pyarrow'. This will allow PandasMaterializer to automatically store the data as a .parquet file instead.

/opt/homebrew/anaconda3/envs/mlops_9/lib/python3.11/site-packages/zenml/materializers/pandas_materializer.py:94: UserWarning: Could not infer format, so each element will be parsed individually, falling back to dateutil. To ensure parsing is consistent and as-expected, please specify a format.
  df = pd.read_csv(f, index_col=0, parse_dates=True)


/opt/homebrew/anaconda3/envs/mlops_9/lib/python3.11/site-packages/great_expectations/data_context/data_context/serializable_data_context.py:225: UserWarning: Warning. An existing great_expectations.yml was found here: /Users/Sofa/Desktop/Innopolis/MLOps/ApartmentPrice/services/gx.
    - No action was taken.
  warnings.warn(message)


FileDataContext loading fluent config

Loading 'datasources' ->
[{'assets': [...], 'name': 'my_pandas_ds', 'type': 'pandas'}]

_PandasDataAsset.dict() - missing config_provider, skipping config substitution

Loaded 'my_pandas_ds' from fluent config

Saving 2 Fluent Datasources to /Users/Sofa/Desktop/Innopolis/MLOps/ApartmentPrice/services/gx/great_expectations.yml

CSVAsset.dict() - missing config_provider, skipping config substitution

PandasDatasource.dict() - missing config_provider, skipping config substitution

PandasDatasource.dict() - missing config_provider, skipping config substitution

Saving 2 Fluent Datasources to /Users/Sofa/Desktop/Innopolis/MLOps/ApartmentPrice/services/gx/great_expectations.yml

CSVAsset.dict() - missing config_provider, skipping config substitution

PandasDatasource.dict() - missing config_provider, skipping config substitution

DataFrameAsset.dict() - missing config_provider, skipping config substitution

PandasDatasource.dict() - missing config_provider, skipping config substitution

Saving 3 Fluent Datasources to /Users/Sofa/Desktop/Innopolis/MLOps/ApartmentPrice/services/gx/great_expectations.yml

CSVAsset.dict() - missing config_provider, skipping config substitution

PandasDatasource.dict() - missing config_provider, skipping config substitution

DataFrameAsset.dict() - missing config_provider, skipping config substitution

PandasDatasource.dict() - missing config_provider, skipping config substitution

PandasDatasource.dict() - missing config_provider, skipping config substitution

Saving 3 Fluent Datasources to /Users/Sofa/Desktop/Innopolis/MLOps/ApartmentPrice/services/gx/great_expectations.yml

CSVAsset.dict() - missing config_provider, skipping config substitution

PandasDatasource.dict() - missing config_provider, skipping config substitution

DataFrameAsset.dict() - missing config_provider, skipping config substitution

PandasDatasource.dict() - missing config_provider, skipping config substitution

DataFrameAsset.dict() - missing config_provider, skipping config substitution

PandasDatasource.dict() - missing config_provider, skipping config substitution

Failed to run step validate.

expectation_suite transformed_data_expectation not found
Traceback (most recent call last):
  File "/opt/homebrew/anaconda3/envs/mlops_9/lib/python3.11/site-packages/zenml/orchestrators/step_launcher.py", line 230, in launch
    self._run_step(
  File "/opt/homebrew/anaconda3/envs/mlops_9/lib/python3.11/site-packages/zenml/orchestrators/step_launcher.py", line 460, in _run_step
    self._run_step_without_step_operator(
  File "/opt/homebrew/anaconda3/envs/mlops_9/lib/python3.11/site-packages/zenml/orchestrators/step_launcher.py", line 535, in _run_step_without_step_operator
    runner.run(
  File "/opt/homebrew/anaconda3/envs/mlops_9/lib/python3.11/site-packages/zenml/orchestrators/step_runner.py", line 199, in run
    return_values = step_instance.call_entrypoint(
                    ^^^^^^^^^^^^^^^^^^^^^^^^^^^^^^
  File "/opt/homebrew/anaconda3/envs/mlops_9/lib/python3.11/site-packages/zenml/steps/base_step.py", line 606, in call_entrypoint
    return self.entrypoint(**validated_args)
           ^^^^^^^^^^^^^^^^^^^^^^^^^^^^^^^^^
  File "/Users/Sofa/Desktop/Innopolis/MLOps/ApartmentPrice/services/airflow/dags/data_prepare.py", line 54, in validate
    X, y = validate_features(X, y)
           ^^^^^^^^^^^^^^^^^^^^^^^
  File "/Users/Sofa/Desktop/Innopolis/MLOps/ApartmentPrice/src/data.py", line 323, in validate_features
    result = checkpoint.run()
             ^^^^^^^^^^^^^^^^
  File "/opt/homebrew/anaconda3/envs/mlops_9/lib/python3.11/site-packages/great_expectations/core/usage_statistics/usage_statistics.py", line 266, in usage_statistics_wrapped_method
    result = func(*args, **kwargs)
             ^^^^^^^^^^^^^^^^^^^^^
  File "/opt/homebrew/anaconda3/envs/mlops_9/lib/python3.11/site-packages/great_expectations/checkpoint/checkpoint.py", line 305, in run
    self._run_validation(
  File "/opt/homebrew/anaconda3/envs/mlops_9/lib/python3.11/site-packages/great_expectations/checkpoint/checkpoint.py", line 480, in _run_validation
    validator: Validator = self._validator or self.data_context.get_validator(
                                              ^^^^^^^^^^^^^^^^^^^^^^^^^^^^^^^^
  File "/opt/homebrew/anaconda3/envs/mlops_9/lib/python3.11/site-packages/great_expectations/data_context/data_context/abstract_data_context.py", line 2338, in get_validator
    expectation_suite = self.get_expectation_suite(
                        ^^^^^^^^^^^^^^^^^^^^^^^^^^^
  File "/opt/homebrew/anaconda3/envs/mlops_9/lib/python3.11/site-packages/great_expectations/data_context/data_context/abstract_data_context.py", line 3035, in get_expectation_suite
    raise gx_exceptions.DataContextError(
great_expectations.exceptions.exceptions.DataContextError: expectation_suite transformed_data_expectation not found

