Caching disabled explicitly for extract.

Step extract has started.

Failed to run step extract.

Unable to find DVC file with output 'data/samples/sample.csv'
Traceback (most recent call last):
  File "/opt/homebrew/anaconda3/envs/mlops_9/lib/python3.11/site-packages/dvc/repo/__init__.py", line 392, in get_data_index_entry
    return index, index[key]
                  ~~~~~^^^^^
  File "/opt/homebrew/anaconda3/envs/mlops_9/lib/python3.11/site-packages/dvc_data/index/index.py", line 682, in __getitem__
    return self._trie[key]
           ~~~~~~~~~~^^^^^
  File "/opt/homebrew/anaconda3/envs/mlops_9/lib/python3.11/site-packages/sqltrie/serialized.py", line 58, in __getitem__
    raw = self._trie[key]
          ~~~~~~~~~~^^^^^
  File "/opt/homebrew/anaconda3/envs/mlops_9/lib/python3.11/site-packages/sqltrie/sqlite/sqlite.py", line 266, in __getitem__
    row = self._get_node(key)
          ^^^^^^^^^^^^^^^^^^^
  File "/opt/homebrew/anaconda3/envs/mlops_9/lib/python3.11/site-packages/sqltrie/sqlite/sqlite.py", line 204, in _get_node
    raise KeyError(key)
KeyError: ('data', 'samples', 'sample.csv')

The above exception was the direct cause of the following exception:

Traceback (most recent call last):
  File "/opt/homebrew/anaconda3/envs/mlops_9/lib/python3.11/site-packages/zenml/orchestrators/step_launcher.py", line 230, in launch
    self._run_step(
  File "/opt/homebrew/anaconda3/envs/mlops_9/lib/python3.11/site-packages/zenml/orchestrators/step_launcher.py", line 460, in _run_step
    self._run_step_without_step_operator(
  File "/opt/homebrew/anaconda3/envs/mlops_9/lib/python3.11/site-packages/zenml/orchestrators/step_launcher.py", line 535, in _run_step_without_step_operator
    runner.run(
  File "/opt/homebrew/anaconda3/envs/mlops_9/lib/python3.11/site-packages/zenml/orchestrators/step_runner.py", line 199, in run
    return_values = step_instance.call_entrypoint(
                    ^^^^^^^^^^^^^^^^^^^^^^^^^^^^^^
  File "/opt/homebrew/anaconda3/envs/mlops_9/lib/python3.11/site-packages/zenml/steps/base_step.py", line 606, in call_entrypoint
    return self.entrypoint(**validated_args)
           ^^^^^^^^^^^^^^^^^^^^^^^^^^^^^^^^^
  File "/Users/Sofa/Desktop/Innopolis/MLOps/ApartmentPrice/services/airflow/dags/data_prepare.py", line 24, in extract
    df, version = read_datastore()
                  ^^^^^^^^^^^^^^^^
  File "/Users/Sofa/Desktop/Innopolis/MLOps/ApartmentPrice/src/data.py", line 124, in read_datastore
    data_url = dvc.api.get_url(
               ^^^^^^^^^^^^^^^^
  File "/opt/homebrew/anaconda3/envs/mlops_9/lib/python3.11/site-packages/dvc/api/data.py", line 84, in get_url
    index, entry = _repo.get_data_index_entry(path)
                   ^^^^^^^^^^^^^^^^^^^^^^^^^^^^^^^^
  File "/opt/homebrew/anaconda3/envs/mlops_9/lib/python3.11/site-packages/dvc/repo/__init__.py", line 394, in get_data_index_entry
    raise OutputNotFoundError(path, self) from exc
dvc.exceptions.OutputNotFoundError: Unable to find DVC file with output 'data/samples/sample.csv'

